<?xml version="1.0" encoding="UTF-8"?>
<robot name="Vector" xmlns:xacro="http://ros.org/wiki/xacro">
  <link name="base_link"/>
  <link name="front_left_wheel"/>
  <link name="front_right_wheel"/>
  <link name="rear_left_wheel"/>
  <link name="rear_right_wheel"/>
  <link name="head"/>
  <link name="full_lift"/>

  <!-- sensors -->
  <link name="camera_link"/>

  <!--joints -->

   <joint name="base_to_lift" type="revolute">
    <parent link="base_link"/>
    <child link="full_lift"/>
    <origin xyz="-0.005 0 0.013"/>
    <limit lower="-0.8" upper="0" effort="5" velocity="10"/>
    <axis xyz="0 1 0"/>
  </joint>

  <joint name="base_to_head" type="revolute">
    <parent link="base_link"/>
    <child link="head"/>
    <origin xyz="0.015 0 0.02"/>
    <limit lower="-0.52" upper="0.17" effort="100" velocity="10"/>
    <dynamics damping="10" friction="1"/>
    <axis xyz="0 1 0"/>
  </joint>

  <joint name="base_to_flw" type="continuous">
    <parent link="base_link"/>
    <child link="front_left_wheel"/>
    <origin xyz="0.03 0.024 -0.012"/>
    <axis xyz="0 1 0"/>
  </joint>

  <joint name="base_to_frw" type="continuous">
    <parent link="base_link"/>
    <child link="front_right_wheel"/>
    <origin xyz="0.03 -0.024 -0.012"/>
    <axis xyz="0 1 0"/>
  </joint>

  <joint name="base_to_rlw" type="continuous">
    <parent link="base_link"/>
    <child link="rear_left_wheel"/>
    <origin xyz="-0.017 0.024 -0.012"/>
    <axis xyz="0 1 0"/>
  </joint>

  <joint name="base_to_rrw" type="continuous">
    <parent link="base_link"/>
    <child link="rear_right_wheel"/>
    <origin xyz="-0.017 -0.024 -0.012"/>
    <axis xyz="0 1 0"/>
  </joint>

   <joint name="head_camera_joint" type="fixed">
    <parent link="head"/>
    <child link="camera_link"/>
    <origin xyz="0.07 0 0.0" rpy="0 0 0"/>
  </joint>
</robot>